[2025-05-20 14:36:54,534] {taskinstance.py:1037} INFO - Dependencies all met for <TaskInstance: ETLWeatherPrint.transform manual__2025-05-20T14:36:52.950432+00:00 [queued]>
[2025-05-20 14:36:54,544] {taskinstance.py:1037} INFO - Dependencies all met for <TaskInstance: ETLWeatherPrint.transform manual__2025-05-20T14:36:52.950432+00:00 [queued]>
[2025-05-20 14:36:54,544] {taskinstance.py:1243} INFO - 
--------------------------------------------------------------------------------
[2025-05-20 14:36:54,544] {taskinstance.py:1244} INFO - Starting attempt 1 of 1
[2025-05-20 14:36:54,544] {taskinstance.py:1245} INFO - 
--------------------------------------------------------------------------------
[2025-05-20 14:36:54,555] {taskinstance.py:1264} INFO - Executing <Task(_PythonDecoratedOperator): transform> on 2025-05-20 14:36:52.950432+00:00
[2025-05-20 14:36:54,561] {standard_task_runner.py:52} INFO - Started process 1456 to run task
[2025-05-20 14:36:54,563] {standard_task_runner.py:76} INFO - Running: ['***', 'tasks', 'run', 'ETLWeatherPrint', 'transform', 'manual__2025-05-20T14:36:52.950432+00:00', '--job-id', '51', '--raw', '--subdir', 'DAGS_FOLDER/01-ETLWeatherPrint.py', '--cfg-path', '/tmp/tmpj2v08hka', '--error-file', '/tmp/tmpeyxk3id2']
[2025-05-20 14:36:54,564] {standard_task_runner.py:77} INFO - Job 51: Subtask transform
[2025-05-20 14:36:54,603] {logging_mixin.py:109} INFO - Running <TaskInstance: ETLWeatherPrint.transform manual__2025-05-20T14:36:52.950432+00:00 [running]> on host fabc4724d39b
[2025-05-20 14:36:54,645] {taskinstance.py:1431} INFO - Exporting the following env vars:
AIRFLOW_CTX_DAG_OWNER=***
AIRFLOW_CTX_DAG_ID=ETLWeatherPrint
AIRFLOW_CTX_TASK_ID=transform
AIRFLOW_CTX_EXECUTION_DATE=2025-05-20T14:36:52.950432+00:00
AIRFLOW_CTX_DAG_RUN_ID=manual__2025-05-20T14:36:52.950432+00:00
[2025-05-20 14:36:54,645] {logging_mixin.py:109} INFO - {"error": {"code": 2008, "message": "API key has been disabled."}}
[2025-05-20 14:36:54,650] {taskinstance.py:1718} ERROR - Task failed with exception
Traceback (most recent call last):
  File "/home/airflow/.local/lib/python3.6/site-packages/pandas/core/indexes/base.py", line 2898, in get_loc
    return self._engine.get_loc(casted_key)
  File "pandas/_libs/index.pyx", line 70, in pandas._libs.index.IndexEngine.get_loc
  File "pandas/_libs/index.pyx", line 101, in pandas._libs.index.IndexEngine.get_loc
  File "pandas/_libs/hashtable_class_helper.pxi", line 1675, in pandas._libs.hashtable.PyObjectHashTable.get_item
  File "pandas/_libs/hashtable_class_helper.pxi", line 1683, in pandas._libs.hashtable.PyObjectHashTable.get_item
KeyError: 'location.localtime_epoch'

The above exception was the direct cause of the following exception:

Traceback (most recent call last):
  File "/home/airflow/.local/lib/python3.6/site-packages/airflow/models/taskinstance.py", line 1334, in _run_raw_task
    self._execute_task_with_callbacks(context)
  File "/home/airflow/.local/lib/python3.6/site-packages/airflow/models/taskinstance.py", line 1460, in _execute_task_with_callbacks
    result = self._execute_task(context, self.task)
  File "/home/airflow/.local/lib/python3.6/site-packages/airflow/models/taskinstance.py", line 1516, in _execute_task
    result = execute_callable(context=context)
  File "/home/airflow/.local/lib/python3.6/site-packages/airflow/decorators/base.py", line 134, in execute
    return_value = super().execute(context)
  File "/home/airflow/.local/lib/python3.6/site-packages/airflow/operators/python.py", line 174, in execute
    return_value = self.execute_callable()
  File "/home/airflow/.local/lib/python3.6/site-packages/airflow/operators/python.py", line 188, in execute_callable
    return self.python_callable(*self.op_args, **self.op_kwargs)
  File "/opt/airflow/dags/01-ETLWeatherPrint.py", line 56, in transform
    transformed_str = transform_weatherAPI(weather_str)
  File "/opt/airflow/dags/transformer.py", line 19, in transform_weatherAPI
    normalized['timestamp'] = normalized['location.localtime_epoch'].apply(lambda s : dt.datetime.fromtimestamp(s).strftime('%Y-%m-%dT%H:%M:%S+02:00'))
  File "/home/airflow/.local/lib/python3.6/site-packages/pandas/core/frame.py", line 2906, in __getitem__
    indexer = self.columns.get_loc(key)
  File "/home/airflow/.local/lib/python3.6/site-packages/pandas/core/indexes/base.py", line 2900, in get_loc
    raise KeyError(key) from err
KeyError: 'location.localtime_epoch'
[2025-05-20 14:36:54,665] {taskinstance.py:1282} INFO - Marking task as FAILED. dag_id=ETLWeatherPrint, task_id=transform, execution_date=20250520T143652, start_date=20250520T143654, end_date=20250520T143654
[2025-05-20 14:36:54,675] {standard_task_runner.py:92} ERROR - Failed to execute job 51 for task transform
Traceback (most recent call last):
  File "/home/airflow/.local/lib/python3.6/site-packages/pandas/core/indexes/base.py", line 2898, in get_loc
    return self._engine.get_loc(casted_key)
  File "pandas/_libs/index.pyx", line 70, in pandas._libs.index.IndexEngine.get_loc
  File "pandas/_libs/index.pyx", line 101, in pandas._libs.index.IndexEngine.get_loc
  File "pandas/_libs/hashtable_class_helper.pxi", line 1675, in pandas._libs.hashtable.PyObjectHashTable.get_item
  File "pandas/_libs/hashtable_class_helper.pxi", line 1683, in pandas._libs.hashtable.PyObjectHashTable.get_item
KeyError: 'location.localtime_epoch'

The above exception was the direct cause of the following exception:

Traceback (most recent call last):
  File "/home/airflow/.local/lib/python3.6/site-packages/airflow/task/task_runner/standard_task_runner.py", line 85, in _start_by_fork
    args.func(args, dag=self.dag)
  File "/home/airflow/.local/lib/python3.6/site-packages/airflow/cli/cli_parser.py", line 48, in command
    return func(*args, **kwargs)
  File "/home/airflow/.local/lib/python3.6/site-packages/airflow/utils/cli.py", line 92, in wrapper
    return f(*args, **kwargs)
  File "/home/airflow/.local/lib/python3.6/site-packages/airflow/cli/commands/task_command.py", line 298, in task_run
    _run_task_by_selected_method(args, dag, ti)
  File "/home/airflow/.local/lib/python3.6/site-packages/airflow/cli/commands/task_command.py", line 107, in _run_task_by_selected_method
    _run_raw_task(args, ti)
  File "/home/airflow/.local/lib/python3.6/site-packages/airflow/cli/commands/task_command.py", line 184, in _run_raw_task
    error_file=args.error_file,
  File "/home/airflow/.local/lib/python3.6/site-packages/airflow/utils/session.py", line 70, in wrapper
    return func(*args, session=session, **kwargs)
  File "/home/airflow/.local/lib/python3.6/site-packages/airflow/models/taskinstance.py", line 1334, in _run_raw_task
    self._execute_task_with_callbacks(context)
  File "/home/airflow/.local/lib/python3.6/site-packages/airflow/models/taskinstance.py", line 1460, in _execute_task_with_callbacks
    result = self._execute_task(context, self.task)
  File "/home/airflow/.local/lib/python3.6/site-packages/airflow/models/taskinstance.py", line 1516, in _execute_task
    result = execute_callable(context=context)
  File "/home/airflow/.local/lib/python3.6/site-packages/airflow/decorators/base.py", line 134, in execute
    return_value = super().execute(context)
  File "/home/airflow/.local/lib/python3.6/site-packages/airflow/operators/python.py", line 174, in execute
    return_value = self.execute_callable()
  File "/home/airflow/.local/lib/python3.6/site-packages/airflow/operators/python.py", line 188, in execute_callable
    return self.python_callable(*self.op_args, **self.op_kwargs)
  File "/opt/airflow/dags/01-ETLWeatherPrint.py", line 56, in transform
    transformed_str = transform_weatherAPI(weather_str)
  File "/opt/airflow/dags/transformer.py", line 19, in transform_weatherAPI
    normalized['timestamp'] = normalized['location.localtime_epoch'].apply(lambda s : dt.datetime.fromtimestamp(s).strftime('%Y-%m-%dT%H:%M:%S+02:00'))
  File "/home/airflow/.local/lib/python3.6/site-packages/pandas/core/frame.py", line 2906, in __getitem__
    indexer = self.columns.get_loc(key)
  File "/home/airflow/.local/lib/python3.6/site-packages/pandas/core/indexes/base.py", line 2900, in get_loc
    raise KeyError(key) from err
KeyError: 'location.localtime_epoch'
[2025-05-20 14:36:54,695] {local_task_job.py:154} INFO - Task exited with return code 1
[2025-05-20 14:36:54,723] {local_task_job.py:264} INFO - 0 downstream tasks scheduled from follow-on schedule check
